Workbook

Sheet Costing Calculator - Integrated
A1: Cost and Pricing Calculator
B2: Set Desired Margin: | C2: 0.65
B4: TOTAL ENGAGEMENT COSTS AND PRICE
B5: Phase | C5: Cost | D5: Price | F5: Per Head Pricing
B6: DESIGN | C6: =H20 | D6: =J20 | F6: # of Participants/Cohort: | G6: 20
B7: DEVELOPMENT | C7: =H38 | D7: =J38 | F7: Cost per Head - CH1: | G7: =D9/G6 | H7: Reflects all design, development and delivery client costs
B8: DELIVERY | C8: =H106 | D8: =J106 | F8: Cost per Head - CH2: | G8: =D8/G6 | H8: Reflects only delivery client costs
B9: Totals: | C9: =SUM(C6:C8) | D9: =SUM(D6:D8)
B11: ITEM | C11: ITEM COST | D11: NOTE | E11: QUANTITY | F11: COST | G11: PM FEE (12%) | H11: COST W PM | I11: MARGIN | J11: CLIENT PRICE
A12: Design | B12: Learning Design Sprint (Design Document) | C12: 6000 | D12: Flat fee | F12: =IF(ISNUMBER(E12), E12*C12, "") | G12: =IF(OR(ISBLANK(F12), NOT(ISNUMBER(F12))), "", F12 * 0.12) | H12: =IF(OR(ISBLANK(G12), NOT(ISNUMBER(G12))), "", F12+G12) | I12: =$C$2 | J12: =IF(AND(ISNUMBER(H12), I12<1), H12/(1-I12), "") | K12: Changed client price from $10K to 6500
B13: F2F Hackathon - 1 Day | C13: 1500 | D13: Flat fee | F13: =IF(ISNUMBER(E13), E13*C13, "") | G13: =IF(OR(ISBLANK(F13), NOT(ISNUMBER(F13))), "", F13 * 0.12) | H13: =IF(OR(ISBLANK(G13), NOT(ISNUMBER(G13))), "", F13+G13) | I13: =$C$2 | J13: =IF(AND(ISNUMBER(H13), I13<1), H13/(1-I13), "") | K13: Change to Design Lab, and a per day costing (not multiple items)
B14: F2F Hackathon - 2 Day | C14: 3000 | D14: Flat fee | F14: =IF(ISNUMBER(E14), E14*C14, "") | G14: =IF(OR(ISBLANK(F14), NOT(ISNUMBER(F14))), "", F14 * 0.12) | H14: =IF(OR(ISBLANK(G14), NOT(ISNUMBER(G14))), "", F14+G14) | I14: =$C$2 | J14: =IF(AND(ISNUMBER(H14), I14<1), H14/(1-I14), "")
B15: F2F Hackathon - 3 Day | C15: 4500 | D15: Flat fee | F15: =IF(ISNUMBER(E15), E15*C15, "") | G15: =IF(OR(ISBLANK(F15), NOT(ISNUMBER(F15))), "", F15 * 0.12) | H15: =IF(OR(ISBLANK(G15), NOT(ISNUMBER(G15))), "", F15+G15) | I15: =$C$2 | J15: =IF(AND(ISNUMBER(H15), I15<1), H15/(1-I15), "")
B16: F2F Hackathon - 4 Day | C16: 6000 | D16: Flat fee | F16: =IF(ISNUMBER(E16), E16*C16, "") | G16: =IF(OR(ISBLANK(F16), NOT(ISNUMBER(F16))), "", F16 * 0.12) | H16: =IF(OR(ISBLANK(G16), NOT(ISNUMBER(G16))), "", F16+G16) | I16: =$C$2 | J16: =IF(AND(ISNUMBER(H16), I16<1), H16/(1-I16), "")
B17: F2F Hackathon - 5 Day | C17: 7500 | D17: Flat fee | F17: =IF(ISNUMBER(E17), E17*C17, "") | G17: =IF(OR(ISBLANK(F17), NOT(ISNUMBER(F17))), "", F17 * 0.12) | H17: =IF(OR(ISBLANK(G17), NOT(ISNUMBER(G17))), "", F17+G17) | I17: =$C$2 | J17: =IF(AND(ISNUMBER(H17), I17<1), H17/(1-I17), "")
B18: Virtual Hackathon - 4hr | C18: 750 | D18: Flat fee | F18: =IF(ISNUMBER(E18), E18*C18, "") | G18: =IF(OR(ISBLANK(F18), NOT(ISNUMBER(F18))), "", F18 * 0.12) | H18: =IF(OR(ISBLANK(G18), NOT(ISNUMBER(G18))), "", F18+G18) | I18: =$C$2 | J18: =IF(AND(ISNUMBER(H18), I18<1), H18/(1-I18), "")
B19: Virtual Hackathon - 8hr | C19: 1500 | D19: Flat fee | F19: =IF(ISNUMBER(E19), E19*C19, "") | G19: =IF(OR(ISBLANK(F19), NOT(ISNUMBER(F19))), "", F19 * 0.12) | H19: =IF(OR(ISBLANK(G19), NOT(ISNUMBER(G19))), "", F19+G19) | I19: =$C$2 | J19: =IF(AND(ISNUMBER(H19), I19<1), H19/(1-I19), "")
B20: DESIGN TOTAL: | F20: =SUM(F12:F19) | G20: =SUM(G12:G19) | H20: =SUM(H12:H19) | J20: =SUM(J12:J19)
B22: ITEM | C22: ITEM COST | D22: NOTE | E22: QUANTITY | F22: COST | G22: PM FEE (12%) | H22: COST W PM | I22: MARGIN | J22: CLIENT PRICE | K22: Simplify - development of up to 2 hrs of virtual content, F2F content, etc. Combine similar things.
A23: Development | B23: Pre-Program Capstone | C23: =M23 | D23: Flat fee (design only) | F23: =IF(ISNUMBER(E23), E23*C23, "") | G23: =IF(OR(ISBLANK(F23), NOT(ISNUMBER(F23))), "", F23 * 0.12) | H23: =IF(OR(ISBLANK(G23), NOT(ISNUMBER(G23))), "", F23+G23) | I23: =$C$2 | J23: =IF(AND(ISNUMBER(H23), I23<1), H23/(1-I23), "") | K23: Eliminate | L23: 6500 | M23: =L23*0.3
B24: Post-Program Capstone | C24: 1950 | D24: Flat fee (design only) | F24: =IF(ISNUMBER(E24), E24*C24, "") | G24: =IF(OR(ISBLANK(F24), NOT(ISNUMBER(F24))), "", F24 * 0.12) | H24: =IF(OR(ISBLANK(G24), NOT(ISNUMBER(G24))), "", F24+G24) | I24: =$C$2 | J24: =IF(AND(ISNUMBER(H24), I24<1), H24/(1-I24), "") | K24: Change to Capstone Session. Not part of a Business impact project, just a program capstone.
B25: Immersive Learning Offsite (1-day F2F) | C25: 5500 | D25: Per day (design only) | F25: =IF(ISNUMBER(E25), E25*C25, "") | G25: =IF(OR(ISBLANK(F25), NOT(ISNUMBER(F25))), "", F25 * 0.12) | H25: =IF(OR(ISBLANK(G25), NOT(ISNUMBER(G25))), "", F25+G25) | I25: =$C$2 | J25: =IF(AND(ISNUMBER(H25), I25<1), H25/(1-I25), "") | K25: Needs to revise down. Call out Per Day.. | L25: 6500 | M25: =L25*0.3
B26: 2-hour Tailored Learning Experience/Session (Learning Circle, Action Learning, AppEx) | C26: =M26 | D26: Flat fee (design only) | F26: =IF(ISNUMBER(E26), E26*C26, "") | G26: =IF(OR(ISBLANK(F26), NOT(ISNUMBER(F26))), "", F26 * 0.12) | H26: =IF(OR(ISBLANK(G26), NOT(ISNUMBER(G26))), "", F26+G26) | I26: =$C$2 | J26: =IF(AND(ISNUMBER(H26), I26<1), H26/(1-I26), "") | L26: 6500 | M26: =L26*0.3
B27: 2-hour Customized Learning Experience/Session (Learning Circle, Action Learning, AppEx) | C27: 2300 | D27: Flat fee (design only) | F27: =IF(ISNUMBER(E27), E27*C27, "") | G27: =IF(OR(ISBLANK(F27), NOT(ISNUMBER(F27))), "", F27 * 0.12) | H27: =IF(OR(ISBLANK(G27), NOT(ISNUMBER(G27))), "", F27+G27) | I27: =$C$2 | J27: =IF(AND(ISNUMBER(H27), I27<1), H27/(1-I27), "")
B28: Insight Cafe | C28: 900 | D28: Flat fee (design only) | F28: =IF(ISNUMBER(E28), E28*C28, "") | G28: =IF(OR(ISBLANK(F28), NOT(ISNUMBER(F28))), "", F28 * 0.12) | H28: =IF(OR(ISBLANK(G28), NOT(ISNUMBER(G28))), "", F28+G28) | I28: =$C$2 | J28: =IF(AND(ISNUMBER(H28), I28<1), H28/(1-I28), "")
B29: Behavior Activation Toolkit | C29: 3750 | D29: Flat fee | F29: =IF(ISNUMBER(E29), E29*C29, "") | G29: =IF(OR(ISBLANK(F29), NOT(ISNUMBER(F29))), "", F29 * 0.12) | H29: =IF(OR(ISBLANK(G29), NOT(ISNUMBER(G29))), "", F29+G29) | I29: =$C$2 | J29: =IF(AND(ISNUMBER(H29), I29<1), H29/(1-I29), "")
B30: Values/Principles Immersive Learning Offsite (F2F) | C30: 5500 | D30: Per day (design only) | F30: =IF(ISNUMBER(E30), E30*C30, "") | G30: =IF(OR(ISBLANK(F30), NOT(ISNUMBER(F30))), "", F30 * 0.12) | H30: =IF(OR(ISBLANK(G30), NOT(ISNUMBER(G30))), "", F30+G30) | I30: =$C$2 | J30: =IF(AND(ISNUMBER(H30), I30<1), H30/(1-I30), "")
B31: Action Learning Brief | C31: 990 | D31: Per unit | F31: =IF(ISNUMBER(E31), E31*C31, "") | G31: =IF(OR(ISBLANK(F31), NOT(ISNUMBER(F31))), "", F31 * 0.12) | H31: =IF(OR(ISBLANK(G31), NOT(ISNUMBER(G31))), "", F31+G31) | I31: =$C$2 | J31: =IF(AND(ISNUMBER(H31), I31<1), H31/(1-I31), "") | K31: What is this? Facilitator debrief?
B32: Dialogue Toolkit | C32: 3750 | D32: Flat fee | F32: =IF(ISNUMBER(E32), E32*C32, "") | G32: =IF(OR(ISBLANK(F32), NOT(ISNUMBER(F32))), "", F32 * 0.12) | H32: =IF(OR(ISBLANK(G32), NOT(ISNUMBER(G32))), "", F32+G32) | I32: =$C$2 | J32: =IF(AND(ISNUMBER(H32), I32<1), H32/(1-I32), "") | K32: convert to a less expensive discussion guide. No deck/content.
B33: Peer Coaching | C33: 450 | D33: Per unit | F33: =IF(ISNUMBER(E33), E33*C33, "") | G33: =IF(OR(ISBLANK(F33), NOT(ISNUMBER(F33))), "", F33 * 0.12) | H33: =IF(OR(ISBLANK(G33), NOT(ISNUMBER(G33))), "", F33+G33) | I33: =$C$2 | J33: =IF(AND(ISNUMBER(H33), I33<1), H33/(1-I33), "")
B34: Principles/Values Workshop (Tailored) | C34: 2300 | D34: Flat fee (design only) | F34: =IF(ISNUMBER(E34), E34*C34, "") | G34: =IF(OR(ISBLANK(F34), NOT(ISNUMBER(F34))), "", F34 * 0.12) | H34: =IF(OR(ISBLANK(G34), NOT(ISNUMBER(G34))), "", F34+G34) | I34: =$C$2 | J34: =IF(AND(ISNUMBER(H34), I34<1), H34/(1-I34), "")
B35: SkillStream (1 path) | C35: 10500 | D35: Flat fee | F35: =IF(ISNUMBER(E35), E35*C35, "") | G35: =IF(OR(ISBLANK(F35), NOT(ISNUMBER(F35))), "", F35 * 0.12) | H35: =IF(OR(ISBLANK(G35), NOT(ISNUMBER(G35))), "", F35+G35) | I35: =$C$2 | J35: =IF(AND(ISNUMBER(H35), I35<1), H35/(1-I35), "")
B36: SkillStream (2 path) | C36: 20100 | D36: Flat fee | F36: =IF(ISNUMBER(E36), E36*C36, "") | G36: =IF(OR(ISBLANK(F36), NOT(ISNUMBER(F36))), "", F36 * 0.12) | H36: =IF(OR(ISBLANK(G36), NOT(ISNUMBER(G36))), "", F36+G36) | I36: =$C$2 | J36: =IF(AND(ISNUMBER(H36), I36<1), H36/(1-I36), "")
B37: Learning Lab | C37: 7500 | D37: Flat fee | F37: =IF(ISNUMBER(E37), E37*C37, "") | G37: =IF(OR(ISBLANK(F37), NOT(ISNUMBER(F37))), "", F37 * 0.12) | H37: =IF(OR(ISBLANK(G37), NOT(ISNUMBER(G37))), "", F37+G37) | I37: =$C$2 | J37: =IF(AND(ISNUMBER(H37), I37<1), H37/(1-I37), "")
B38: DEVELOPMENT TOTAL: | F38: =SUM(F23:F37) | G38: =SUM(G23:G37) | H38: =SUM(H23:H37) | J38: =SUM(J23:J37)
G39: =IF(OR(ISBLANK(F39), NOT(ISNUMBER(F39))), "", F39 * 0.12) | H39: =IF(OR(ISBLANK(G39), NOT(ISNUMBER(G39))), "", F39+G39)
B40: ITEM | C40: ITEM COST | D40: NOTE | E40: QUANTITY | F40: COST | G40: PM FEE (12%) | H40: COST W PM | I40: MARGIN | J40: CLIENT PRICE
A41: Delivery | B41: ASSESSMENT
B42: CMI Assessment | C42: 100 | D42: Per person | F42: =IF(ISNUMBER(E42), E42*C42, "") | G42: =IF(OR(ISBLANK(F42), NOT(ISNUMBER(F42))), "", F42 * 0.12) | H42: =IF(OR(ISBLANK(G42), NOT(ISNUMBER(G42))), "", F42+G42) | I42: 0 | J42: =IF(AND(ISNUMBER(H42), I42<1), H42/(1-I42), "")
B43: CMI 360 Report | C43: 250 | D43: Per person | F43: =IF(ISNUMBER(E43), E43*C43, "") | G43: =IF(OR(ISBLANK(F43), NOT(ISNUMBER(F43))), "", F43 * 0.12) | H43: =IF(OR(ISBLANK(G43), NOT(ISNUMBER(G43))), "", F43+G43) | I43: 0 | J43: =IF(AND(ISNUMBER(H43), I43<1), H43/(1-I43), "")
...

Sheet Calculator
A1: Coaching Calculator
A2: Selected Tier:
A3: Coaching Cost Summary
A4: ITEM | B4: ITEM COST | C4: NOTE | D4: QUANTITY | E4: COST | F4: PM FEE | G4: COST W PM | H4: MARGIN | I4: CLIENT PRICE
A5: ROADMAP | B5: =if(ISNUMBER(D5),B32+H26," ") | C5: Per person | D5: =E31 | E5: =IF(ISNUMBER(D5), D5*B5, "") | F5: =IF(ISNUMBER(D5),D5*B31," ") | G5: =IF(ISNUMBER(D5), E5+F5, " ") | H5: =$B$16 | I5: =IF(AND(ISNUMBER(G5), H5<1), H32, "")
A6: IGNITE | B6: =IF(ISNUMBER(D6),B50+H42," ") | C6: Per person | D6: =E49 | E6: =IF(ISNUMBER(D6), D6*B6, "") | F6: =IF(ISNUMBER(D6),D6*B49," ") | G6: =IF(ISNUMBER(D6), E6+F6, " ") | H6: =$B$16 | I6: =IF(AND(ISNUMBER(G6), H6<1), H50, "")
A7: ASCENT | B7: =IF(ISNUMBER(D7),B68+H60," ") | C7: Per person | D7: =E67 | E7: =IF(ISNUMBER(D7), D7*B7, "") | F7: =IF(ISNUMBER(D7),D7*B67," ") | G7: =IF(ISNUMBER(D7), E7+F7, " ") | H7: =$B$16 | I7: =IF(AND(ISNUMBER(G7), H7<1), H68, "")
A8: SPARK 1 | B8: =IF(ISNUMBER(D8),B84+H78," ") | C8: Per person | D8: =E83 | E8: =IF(ISNUMBER(D8), D8*B8, "") | F8: =IF(ISNUMBER(D8),D8*B83," ") | G8: =IF(ISNUMBER(D8), E8+F8, " ") | H8: =$B$16 | I8: =IF(AND(ISNUMBER(G8), H8<1), H84, "")
A9: SPARK 2 | B9: =IF(ISNUMBER(D9),B102+H95," ") | C9: Per person | D9: =E101 | E9: =IF(ISNUMBER(D9), D9*B9, "") | F9: =IF(ISNUMBER(D9),D9*B101," ") | G9: =IF(ISNUMBER(D9), E9+F9, " ") | H9: =$B$16 | I9: =IF(AND(ISNUMBER(G9), H9<1), H102, "")
A10: AIIR Vista (6 months) | B10: =IF(ISNUMBER(D10),B120+H111," ") | C10: Per person | D10: =E119 | E10: =IF(ISNUMBER(D10), D10*B10, "") | F10: =IF(ISNUMBER(D10),D10*B119," ") | G10: =IF(ISNUMBER(D10), E10+F10, " ") | H10: =$B$16 | I10: =IF(AND(ISNUMBER(G10), H10<1), H120, "")
A11: AIIR Vista (12 months) | B11: =IF(ISNUMBER(D11),B138+H129," ") | C11: Per person | D11: =E137 | E11: =IF(ISNUMBER(D11), D11*B11, "") | F11: =IF(ISNUMBER(D11),D11*B137," ") | G11: =IF(ISNUMBER(D11), E11+F11, " ") | H11: =$B$16 | I11: =IF(AND(ISNUMBER(G11), H11<1), H138, "")
A12: EXECUTIVE COACHING TOTAL: | E12: =SUM(E3:E9) | F12: =SUM(F3:F9) | G12: =SUM(G3:G9) | I12: =SUM(I3:I9)
A14: Set Bill Rate and Margin for the Engagement | D14: Coach Hourly Rate Table | E14: Tier 1 | F14: Tier 2 | G14: C-Suite
A15: Coaching Bill Rate: | B15: 350 | D15: Mature Market | E15: 350 | F15: 250 | G15: 600
A16: Margin: | B16: 0.65 | D16: Emerging Market | E16: 300 | F16: 200 | G16: 500
A19: ROADMAP
A20: Sessions | B20: Coaching Hours | D20: Assessments & Fees | E20: # | F20: Rate | G20: Cost
A21: Initial Coaching Session | B21: 0.5 | D21: Coaching Zone Fee - months | E21: 6 | F21: 75 | G21: =E21*F21
A22: Stakeholder 1: Agenda Setting Meeting | B22: 1 | D22: LD12 360º | E22: 1 | F22: 350 | G22: =E22*F22
A23: Developmental History Interview | B23: 1.5 | D23: LD12 | F23: 150 | G23: =E23*F23
A24: Assessment Feedback Session | B24: 2 | D24: Hogan Insight | F24: 300 | G24: =E24*F24
A25: Development Planning Session | B25: 1 | D25: TES | F25: 500 | G25: =E25*F25
A26: Stakeholder 2: Presentation of SDP | B26: 1 | D26: Other: | G26: =E26*F26
A27: 5 Implementation Session | B27: 5 | D27: Other: | G27: =E27*F27
A28: Stakeholder 3: Wrap-Up Session | B28: 1 | G28: Total Assessments & Fees per Participant: | H28: =SUM(G21:G27)
A29: Total Hours per Participant: | B29: =sum(B21:B28) | G29: Total Services including margin: | H29: =B32/(1-$B$16)
A30: Total Coach Cost | B30: =B29*$B$15 | G30: Engagement Total Per Participant: | H30: =SUM(H26:H29)
A31: PM Fee (12%) | B31: =B30*0.12 | D31: # of Participants
A32: Total Services Cost (without margin): | B32: =SUM(B30:B31) | G32: Total for Engagement: | H32: =H30*E31
A35: IGNITE
A36: Sessions | B36: Coaching Hours | D36: Assessments & Fees | E36: # | F36: Rate | G36: Cost
A37: Initial Coaching Session | B37: 0.5 | C37: Default: 30 min | D37: Coaching Zone Fee - months | E37: 9 | F37: 75 | G37: =E37*F37
A38: Stakeholder 1: Agenda Setting Meeting | B38: 1 | C38: Default: 1 hr Min: 30 min | D38: LD12 360º | E38: 0 | F38: 350 | G38: =E38*F38
A39: Developmental History Interview | B39: 2 | C39: Default: 2 hrs Min: 90 min | D39: LD12 | E39: 1 | F39: 150 | G39: =E39*F39
A40: Interview-based 360º (up to 8 interviews) | B40: =(45*8)/60 | C40: Default: 8 mtgs * 45 min each = 6 hrs Min: 5 mtgs * 45 min each = 3.75 hrs | D40: Hogan Insight | E40: 1 | F40: 300 | G40: =E40*F40
A41: Assessment Feedback Session | B41: 2 | C41: Default: 2 hrs Min: 90 min | D41: TES | F41: 500 | G41: =E41*F41
A42: Development Planning Session | B42: 1 | C42: Default: 1 hr Min: 0 hrs | D42: Other: | G42: =E42*F42
A43: Stakeholder 2: Presentation of SDP | B43: 1 | C43: Default: 1 hr Min: 30 min | D43: Other: | G43: =E43*F43
A44: 8 Implementation Sessions | B44: 8 | C44: Default/Always: 8 sessions * 1 hr each | G44: Total Assessments & Fees per Participant: | H44: =SUM(G37:G43)
A45: Stakeholder 3: Mid-Point Check In | B45: 1 | C45: Default: 1 hr Min: 30 min
...

Sheet Deliverable Glossary
B1: DELIVERABLE | C1: DESCRIPTION
A2: Design | B2: Learning Design Sprint (Design Document) | C2: A focused, collaborative engagement that helps organizations move from strategy to a high-level program design and implementation plan – fast. Provides a structured process (design document) to clarify purpose, align on design principles, and map out a launch plan for each program.
B3: F2F Hackathon - 1 Day | C3: A collaborative, creative 1-day experience that brings together AIIR solutions architects and client partners to co-create learning deliverables.
B4: F2F Hackathon - 2 Day | C4: A collaborative, creative 2-day experience that brings together AIIR solutions architects and client partners to co-create learning deliverables.
B5: F2F Hackathon - 3 Day | C5: A collaborative, creative 3-day experience that brings together AIIR solutions architects and client partners to co-create learning deliverables.
B6: F2F Hackathon - 4 Day | C6: A collaborative, creative 4-day experience that brings together AIIR solutions architects and client partners to co-create learning deliverables.
B7: F2F Hackathon - 5 Day | C7: A collaborative, creative 5-day experience that brings together AIIR solutions architects and client partners to co-create learning deliverables.
B8: Virtual Hackathon - 4hr | C8: A collaborative, creative 1/2-day virtual experience that brings together AIIR solutions architects and client partners to co-create learning deliverables.
B9: Virtual Hackathon - 8hr | C9: A collaborative, creative 1-day virtual experience that brings together AIIR solutions architects and client partners to co-create learning deliverables.
B11: DELIVERABLE | C11: DESCRIPTION
A12: Development | B12: Pre-Program Capstone | C12: A session designed to introduce a capstone project/business challenges, divide participants into teams, and provide structured time to plan their project and assign accountabilities. Available F2F or Virtual.
B13: Post-Program Capstone | C13: A session designed to give participants a platform to present back their results and recommendations following the completion of their chosen capstone project. Available F2F or Virtual.
B14: Immersive Learning Offsite (F2F) | C14: Bespoke learning event design bringing together a unique combination of AIIR content, new models, immersive experiences, simulated scenarios, and keynote speakers.
B15: Learning Circle (Virtual) | C15: A structured, yet informal, group reinforcement experience designed to foster reflection, accountability, and peer-supported growth
B16: Immersive Virtual Engagement - Nudge | C16: Sustainment tool designed to reinforce behavior learned in an Immersive Learning Offsite, and provide participants with a challenge/case study for an upcoming Immersive Virtual Engagement Session.
B17: Immersive Virtual Engagement - Session | C17: Bespoke virtual learning session designed to drive application of learning around an organizational challenge or case study.
B18: Insight Cafe | C18: Engagement session designed to build belief in a change initiative/learning journey. Participants are divided into groups, discuss provocative questions related to the journey, and what it means for them. Available F2F or Virtual.
B19: Skill-Build Workshop (Standard) | C19: No changes to the content of one standard AIIR module. For clients who are satisfied with an AIIR module, right of the shelf, with no content design changes.
B20: Skill-Build Workshop (Tailored) | C20: Light content changes to one standard AIIR module. For clients who are satisfied with an AIIR module, but would like the messaging and look of the content to fit better with their culture.
B21: Skill-Build Workshop (Customized) | C21: Significant changes to one standard AIIR module OR the merging of multiple AIIR modules into a new fit-for-purpose session. For clients who are satisfied with an AIIR module, but would like to alter the exercises/experience to fit their needs OR clients who want to draw from multiple AIIR modules to create a fit-for-purpose experience.
B22: Skill-Build Workshop (Bespoke) | C22: Client can request brand new content or change content any way they wish. For clients who are interested in combining AIIR content, with non-AIIR content, or want a “from scratch” experience.
B23: Behavior Activation Toolkit | C23: Sustainment tool designed to help participants practice the behaviors they’ve learned back on the job. Interactive PDF (12-15 pages) with the following inclusions: * Program roadmap * Skill-building tips * 3x tools per behavior/skill * List of further resources (books, articles, TED talks)
B24: Dialogue Toolkit (Leader as Teacher) | C24: Sustainment tool designed to help participants facilitate discussions about the content with others who have attended a learning program. Includes: * 15-20 slide facilitation deck * Facilitation notes (in deck)
... B26: Peer Coaching | C26: Either digital (interactive PDF) or physical conversation guide to facilitate peer-to-peer reflection and relationships. Contains: * Overview of journey * Guidance on interactions and conversations * Journey specific conversation prompts * Areas for note keeping and reflections
B27: Action Learning
B28: Principles/Values Workshop (Standard) | C28: No changes to the content of one standard AIIR module. For clients who are satisfied with an AIIR module to represent one of their leadership principles/values right of the shelf, with no content design changes. (NOTE: requires a strong facilitator brief to ensure connection to desired leadership principle/value.
B29: Principles/Values Workshop (Tailored) | C29: Light content changes to one standard AIIR module. For clients who are satisfied with an AIIR module to represent one of their leadership principles/values, but would like the messaging and look of the content to fit better with their culture.
B30: Principles/Values Workshop (Customized) | C30: Significant changes to one standard AIIR module OR the merging of multiple AIIR modules into a new fit-for-purpose session. For clients who are satisfied with an AIIR module to represent one of their leadership principles/values, but would like to alter the exercises/experience to fit their needs OR clients who want to draw from multiple AIIR modules to create a fit-for-purpose experience.
B31: Principles/Values Workshop (Bespoke) | C31: Client can request brand new content or change content any way they wish. For clients who are interested in combining AIIR content, with non-AIIR content, or want a “from scratch” experience around one of their leadership principles/values.
B32: Group Coaching | C32: Sustainment session, led by an expert AIIR coach, designed to reinforce behavior by reviewing previous content and/or creating deeper, unstructured discussion around it. Available F2F or Virtual.
B33: Assessment Group Debrief | C33: 2 hour interactive session designed to help participants understand the structure and science behind the assessment they completed, the benefits of taking it, how to interpret their results, and first reactions on what this means for them. Available F2F or Virtual.
B34: SkillStream (1 path) | C34: Highly interactive custom sustainment eLearning designed for participants to take a “watch” then “practice” approach individually, OR in small groups.
B35: SkillStream (2 path) | C35: Highly interactive custom sustainment eLearning designed for participants to take a “watch” then “practice” approach individually, AND in small groups.
B36: Learning Lab | C36: Custom sustainment eLearning designed to present participants common scenarios for which to practice their skills. Participants complete 3-5 case studies/scenarios of varying levels of difficulty, and receive tips and tactics as they work their way through scenarios.
B38: DELIVERABLE | C38: DESCRIPTION
A39: Assessment | B39: CMI Assessment | C39: Individual CMI assessment with detailed description of CMI model, individualized scores and development suggestions, and action planning tool included.
B40: CMI 360 | C40: 360 CMI assessment with comparison of self vs. rater scores, detailed scaled data including item by item breakdown and rater agreement metric, open-ended feedback, and a variety of data displays for easy analysis.
B41: CMI Group Report | C41: CMI assessment that compares scores for an entire cohort of respondents, including group comparison of coaching style and average coaching strategy scores.
B42: LD12™ Assessment (Self Report) | C42: The LD12™ provides a comprehensive map of leadership skills, pinpointing leaders' signature strengths and development opportunities.
B43: LD12™ 360 Assessment | C43: The LD12™ 360 combines self-assessment on leadership skills with comprehensive insights from direct reports, peers, and managers to get an individual’s complete leadership picture.
...

Sheet Tracker
A1: engagement_id | B1: created_at | C1: transcript_filename | D1: client_company | E1: coachee_name | F1: hubspot_deal_id | G1: coach_name | H1: tier | I1: bill_rate | J1: num_participants | K1: price_per_participant | L1: total_engagement_price | M1: payment_structure | N1: net_days | O1: pricing_approval_status | P1: pricing_approved_by | Q1: pricing_approved_at | R1: rationale_doc_url | S1: calculator_url | T1: sow_doc_url | U1: sow_approval_status | V1: sow_approved_by | W1: sow_approved_at | X1: client_email | Y1: sent_at | Z1: archive_folder_url | AA1: full_variables_json
